Workbook

Sheet Cover Sheet
D1: By | E1: Date
D2: CDC | E2: 46097
B4: MANUFACTURING INSTRUCTIONS
B5: Order of Operations
B6: OP. # | C6: DESCRIPTION | D6: OPERATOR | E6: DATE
B7: 1 | C7: ISSUE MATERIALS PER BOM
B8: 2 | C8: APPLY PTFE TAPES TO CONDUCTOR
B9: 3 | C9: APPLY PTFE TAPES TO CABLE
B10: 4 | C10: PERFORM TAPE CONDITIONING
B11: 5 | C11: APPLY FLAT WIRE TAPE (SPIRAL) AND ALUMINIZED POLYIMIDE TAPE TO CABLE
B12: 6 | C12: PERFORM SIGNAL INTEGRITY TEST
B13: 7 | C13: BRAID CABLE
B14: 8 | C14: PERFORM SIGNAL INTEGRITY TEST
B15: 9 | C15: MIX COMPOUNDS
B16: 10 | C16: EXTRUDE CABLE
B17: 11 | C17: PERFORM SIGNAL INTEGRITY TEST
B18: 12 | C18: MARK & RESPOOL CABLE
... B21: 15 | C21: SCAN COMPLETED JOB PACKAGE AND ROUTE TO ENGINEERING

Sheet Taping (3-Bay)
A1: Process Step | E1: Machine ID | I1: By | J1: Date
A2: Taping #1 | E2: WTM 3-Bay | I2: ='Cover Sheet'!D2 -> CDC | J2: ='Cover Sheet'!E2 -> 46097
B4: Materials | H4: REFERENCE AP96-007
B5: Description | D5: Part Number
B6: Tape #1 | D6: - | G6: Estimated Footage
B7: Tape #2 | D7: 962-96000-05L0150
B8: Tape #3 | D8: 962-96000-05L0200
D9: Min. | E9: Nom. | F9: Max. | H9: Actual | I9: Oper. | J9: Date
B10: "PO" LaserLink OD (Avg, Inch) | D10: 0.0284 | E10: 0.0287 | F10: 0.029
B12: Caterpillar Gap | D12: - | E12: 6.85 | F12: -
B13: Caterpillar Die Size | D13: -
B14: Pay-Off Dancer Set Point (%) | D14: - | E14: - | F14: -
B15: Pay-Off Dancer Valve Set Point (%) | D15: - | E15: - | F15: -
B16: Pay-Off Dancer Load Cell Set Point (N) | D16: - | E16: - | F16: -
B17: Pay-Off Torque Set Point (%) | D17: - | E17: 0.2 | F17: -
B18: Pay-Off Pull Set Point (N) | D18: - | E18: 10 | F18: -
B19: Take-Up Torque Set Point (%) | D19: - | E19: 0.2 | F19: -
B21: Tape #1, Lay Direction | D21: -
B22: Tape #1, Pitch Set-Point | D22: - | E22: - | F22: -
B23: Tape #1, Overlap | D23: -
B24: Tape #1, Tension (N) | D24: - | E24: - | F24: -
B25: Tape #1, Roller #1/#2 Position | D25: -
B27: "H1" LaserLink OD (Avg, Inch) | D27: 0.0284 | E27: 0.0287 | F27: 0.029
B29: Tape #2, Lay Direction | D29: Z-DIRECTION
B30: Tape #2, Pitch Set-Point | D30: - | E30: 0.1065 | F30: -
B31: Tape #2, Overlap | D31: 1/2 WRAP
B32: Tape #2, Tension (N) | D32: - | E32: 4 | F32: -
B33: Tape #2, Roller #1/#2 Position | D33: 0 / 6
B35: "H2" LaserLink OD (Avg, Inch) | D35: - | E35: 0.041 | F35: -
B37: Tape #3, Lay Direction | D37: S-DIRECTION
B38: Tape #3, Pitch Set-Point | D38: - | E38: 0.14 | F38: -
B39: Tape #3, Overlap | D39: 1/2 WRAP
B40: Tape #3, Tension (N) | D40: - | E40: 4 | F40: -
B41: Tape #3, Roller #1/#2 Position | D41: 1 / 5
B43: "H3" LaserLink OD (Avg, Inch) | D43: - | E43: 0.053 | F43: -
B45: Line Speed (ft/min) | D45: - | E45: 7 | F45: -
B47: "TU" LaserLink OD (Avg, Inch) | D47: - | E47: 0.053 | F47: -
B49: Take-Up Spool Size | D49: AT12679 (24" X 14")
B51: Notes:

Sheet Taping (3-Bay) (2)
A1: Process Step | E1: Machine ID | I1: By | J1: Date
A2: Taping #2 | E2: WTM 3-Bay | I2: ='Cover Sheet'!D2 -> CDC | J2: ='Cover Sheet'!E2 -> 46097
B4: Materials | H4: REFERENCE AP96-007
B5: Description | D5: Part Number
B6: Tape #1 | D6: - | G6: Estimated Footage
B7: Tape #2 | D7: 962-96000-05L0200
B8: Tape #3 | D8: 962-96000-05L0250
D9: Min. | E9: Nom. | F9: Max. | H9: Actual | I9: Oper. | J9: Date
B10: "PO" LaserLink OD (Avg, Inch) | D10: ='Taping (3-Bay)'!D47 -> - | E10: ='Taping (3-Bay)'!E47 -> 0.053 | F10: ='Taping (3-Bay)'!F47 -> -
B12: Caterpillar Gap | D12: - | E12: 6.85 | F12: -
B13: Caterpillar Die Size | D13: -
B14: Pay-Off Dancer Set Point (%) | D14: - | E14: - | F14: -
B15: Pay-Off Dancer Valve Set Point (%) | D15: - | E15: - | F15: -
B16: Pay-Off Dancer Load Cell Set Point (N) | D16: - | E16: - | F16: -
B17: Pay-Off Torque Set Point (%) | D17: - | E17: 0.45 | F17: -
B18: Pay-Off Pull Set Point (N) | D18: - | E18: 10 | F18: -
B19: Take-Up Torque Set Point (%) | D19: - | E19: 0.2 | F19: -
B21: Tape #1, Lay Direction | D21: -
B22: Tape #1, Pitch Set-Point | D22: - | E22: - | F22: -
B23: Tape #1, Overlap | D23: -
B24: Tape #1, Tension (N) | D24: - | E24: - | F24: -
B25: Tape #1, Roller #1/#2 Position | D25: -
B27: "H1" LaserLink OD (Avg, Inch) | D27: - | E27: 0.053 | F27: -
B29: Tape #2, Lay Direction | D29: Z-DIRECTION
B30: Tape #2, Pitch Set-Point | D30: - | E30: 0.074 | F30: -
B31: Tape #2, Overlap | D31: 2/3 WRAP
B32: Tape #2, Tension (N) | D32: - | E32: 4 | F32: -
B33: Tape #2, Roller #1/#2 Position | D33: /
B35: "H2" LaserLink OD (Avg, Inch) | D35: - | E35: 0.067 | F35: -
B37: Tape #3, Lay Direction | D37: S-DIRECTION
B38: Tape #3, Pitch Set-Point | D38: - | E38: 0.09 | F38: -
B39: Tape #3, Overlap | D39: 2/3 WRAP
B40: Tape #3, Tension (N) | D40: - | E40: 4 | F40: -
B41: Tape #3, Roller #1/#2 Position | D41: 1 / 5
B43: "H3" LaserLink OD (Avg, Inch) | D43: 0.079 | E43: 0.081 | F43: 0.083
B45: Line Speed (ft/min) | D45: - | E45: 4 | F45: -
B47: "TU" LaserLink OD (Avg, Inch) | D47: 0.079 | E47: 0.081 | F47: 0.083
B49: Take-Up Spool Size | D49: AT12679 (24" X 14")
B51: Notes:

Sheet Tape Conditioning
A1: Process Step | E1: Machine ID | I1: By | J1: Date
A2: Tape Conditioning | E2: Oven | I2: ='Cover Sheet'!D2 -> CDC | J2: ='Cover Sheet'!E2 -> 46097 | K2: ='[1]Cover Sheet'!$F$2 -> ETH
G4: Estimated Footage
E7: OVEN: | H7: JPW Wisconsin
D9: Min. | E9: Nom. | F9: Max. | H9: Actual | I9: Oper. | J9: Date
A10: Oven Temperature (°F) | D10: 365 | E10: 375 | F10: 385
A11: Minimum Bake Duration (Hours) | D11: 8
E13: TIME IN:
E15: TIME OUT:
B23: Notes:

Sheet Spiral Shield
A1: Process Step | E1: Machine ID | I1: By | J1: Date
A2: Spiral Shield | E2: WTM 2-Bay | I2: ='Cover Sheet'!D2 -> CDC | J2: ='Cover Sheet'!E2 -> 46097
B4: Materials | H4: REFERENCE AP96-008
B5: Description | C5: Part Number | D5: Part Number | G5: Estimated Footage
B6: Flat Wire | C6: 962-96001-0895 | D6: 962-96001-SPC-2.5-0300
B7: Tape | C7: 962-96002-01-0375 | D7: 962-96003-ALK-1.4-0250
B8: Take-Up Spool | C8: 962-96002-01-0375 | D8: AT12679 (24"x14")
D9: Min. | E9: Nom. | F9: Max. | H9: Actual | I9: Oper. | J9: Date
A10: "PO" LaserLink OD (Avg, Inch) | D10: ='Taping (3-Bay) (2)'!D47 -> 0.079 | E10: ='Taping (3-Bay) (2)'!E47 -> 0.081 | F10: ='Taping (3-Bay) (2)'!F47 -> 0.083
A12: Caterpillar Gap | D12: - | E12: 1.03 | F12: -
A13: Pay-Off Torque Set Point (%) | D13: - | E13: 0.3 | F13: -
A14: Take-Up Torque Set Point (%) | D14: - | E14: 0.3 | F14: -
A16: Flat Wire Lay Direction | D16: S-DIRECTION
A17: Number of Carriers | D17: 8
A18: Flat Wire Pitch Set-Point | D18: - | E18: 2.5 | F18: -
A19: Head #1 Die Size | D19: 0.085
A21: "H1" LaserLink OD (Avg, Inch) | D21: 0.084 | E21: 0.086 | F21: 0.088
A23: Tape Lay Direction | D23: Z-DIRECTION / FOIL IN
A24: Tape Pitch Set-Point | E24: 0.144
A25: Tape # 2, Overlap | D25: 2/3 WRAP
A26: Head #2, Tension (N) | D26: - | E26: 6 | F26: -
A27: Tape Roller #1 Position | D27: 1
A28: Tape Roller #2 Position | D28: 1
A30: "H2" LaserLink OD (Avg, Inch) | D30: 0.089 | E30: 0.091 | F30: 0.093
A32: Line Speed (ft/min) | D32: - | E32: 7 | F32: -
A34: "TU" LaserLink OD (Avg, Inch) | D34: 0.089 | E34: 0.091 | F34: 0.093
B36: Notes:

Sheet SI Testing (Post-Spiral)
A1: Process Step | E1: Machine ID | I1: By | J1: Date
A2: SI Testing (Post-Spiral) | E2: VNA #1 | I2: ='Cover Sheet'!D2 -> CDC | J2: ='Cover Sheet'!E2 -> 46097
I4: REFERENCE AP96-048
B5: Electrical (Signal Integrity) Testing
B6: Operation # | C6: Description
B7: 1 | C7: Cut 25-foot section of cable, prep ends and terminate to test PCB.
B8: 2 | C8: Connect to Network Analyzer, enter job information and acquire data.
B9: 3 | C9: Print summary datasheet and include with job package.
B10: 4 | C10: Record "Pass/Fail" test result below.
H11: Actual | I11: Oper. | J11: Date
D12: Pass / Fail?
D13: Test Plot Attached?
B18: Notes:

Sheet Braiding
A1: Process Step | E1: Machine ID | I1: By | J1: Date
A2: Braiding | E2: Niehoff Braider | I2: ='Cover Sheet'!D2 -> CDC | J2: ='Cover Sheet'!E2 -> 46097
B4: Materials | H4: REFERENCE AP96-006
B5: Description | D5: Part Number | G5: Estimated Footage
B6: Braid Material | D6: 961-96207-SCC-40-8
B7: Take-Up Spool | D7: AT12679 (24" x 14")
D8: Min. | E8: Nom. | F8: Max.
A9: Braid Coverage (%) | D9: 0.9 | E9: 0.9729 | F9: 1
A10: Braid Angle (°) | D10: 35 | E10: 38.07 | F10: 45 | H10: Actual | I10: Oper. | J10: Date
A12: Incoming OD (in) | D12: ='Spiral Shield'!D34 -> 0.089 | E12: ='Spiral Shield'!E34 -> 0.091 | F12: ='Spiral Shield'!F34 -> 0.093
A13: Number of Carriers | D13: 16
A14: Ends Per Carrier | D14: - | E14: 8 | F14: -
A15: Picks Per Inch | D15: - | E15: 20.5 | F15: -
A16: Braider RPM Setting | D16: - | E16: 30 | F16: -
A18: Die Size (Inch) | D18: - | E18: 0.12 | F18: -
A19: Tension Spring Color
A21: Variable Picks | D21: OFF
A22: Minimum Variable Picks | D22: - | E22: - | F22: -
A23: Maximum Variable Picks | D23: - | E23: - | F23: -
A24: Transition Length (Inch) | D24: - | E24: - | F24: -
A26: Take-Up Traverse Setting | D26: - | E26: 1.8 | F26: -
A27: Take-Up Tension Setting | D27: - | E27: 1.8 | F27: -
A29: Outgoing OD (Inch) | D29: 0.102 | E29: 0.104 | F29: 0.106
A30: Max Weight (lbs/1,000FT) | D30: -
B32: Notes:

Sheet SI Testing (Post-Braid)
A1: Process Step | E1: Machine ID | I1: By | J1: Date
A2: SI Testing (Post-Braid) | E2: VNA #1 | I2: ='Cover Sheet'!D2 -> CDC | J2: ='Cover Sheet'!E2 -> 46097
I4: REFERENCE AP96-048
B5: Electrical (Signal Integrity) Testing
B6: Operation # | C6: Description
B7: 1 | C7: Cut 25-foot section of cable, prep ends and terminate to test PCB.
B8: 2 | C8: Connect to Network Analyzer, enter job information and acquire data.
B9: 3 | C9: Print summary datasheet and include with job package.
B10: 4 | C10: Record "Pass/Fail" test result below.
H11: Actual | I11: Oper. | J11: Date
D12: Pass / Fail?
D13: Test Plot Attached?
B18: Notes:

Sheet Mixing
A1: Process Step | E1: Machine ID | H1: By | I1: Date
A2: Mixing | E2: N/A | H2: ='Cover Sheet'!D2 -> CDC | I2: ='Cover Sheet'!E2 -> 46097
B4: Materials
B5: Description | C5: Ratio | E5: Part Number | G5: Batch/Lot #
B6: Item #1 | C6: 0.94 | E6: GPS288
B7: Item #2 | C7: 0.04 | E7: GPS247-6 | H7: Total Amount (lbs):
B8: Item #3 | C8: 0.02 | E8: GPS247-9
B10: Batch # | C10: Item #1 (lbs) | E10: Item #2 (lbs) | G10: Item #3 (lbs) | H10: Oper. | I10: Date
B11: #1
B12: #2
B13: #3
B14: #4
B15: #5
B16: #6
B17: #7
B18: #8
B19: #9
B20: #10
B23: Notes:

Sheet Extrusion (Graham)
A1: Process Step | E1: Machine ID | J1: By | K1: Date
A2: Extrusion | E2: Graham Extruder | J2: ='Cover Sheet'!D2 -> CDC | K2: ='Cover Sheet'!E2 -> 46097 | L2: ETH
B4: Materials | I4: REFERENCE AP96-001
B5: Description | C5: Ratio | E5: Part Number
B6: Base | C6: =Mixing!C6 -> 0.94 | D6: =Mixing!E6 -> GPS288 | I6: Estimated Footage
B7: Color #1 | C7: =Mixing!C7 -> 0.04 | D7: =Mixing!E7 -> GPS247-6
B8: Color #2 | C8: =Mixing!C8 -> 0.02 | D8: =Mixing!E8 -> GPS247-9
B9: Take-Up Spool | C9: N/A | D9: AT12679 (24" X 14" )
D11: Min. | E11: Nom. | F11: Max. | I11: Actual | J11: Oper. | K11: Date
B12: Incoming O.D. (in) | D12: =Braiding!D29 -> 0.102 | E12: =Braiding!E29 -> 0.104 | F12: =Braiding!F29 -> 0.106
B13: Dry Time (hrs) | D13: - | F13: -
B14: Dry Temp. (°C) | D14: - | F14: -
B15: Wire Pre-Heat Setting (°F/V) | F15: 600/5
B16: Tip | D16: 0.47
B17: Die | D17: 0.61
B18: Filter Pack Mesh Size | D18: 80/80
B19: Screw | D19: GP
B20: Screw RPM | D20: - | E20: 7 | F20: -
B21: Barrel Zone #1 Temp. (°F) | D21: - | E21: 590 | F21: -
B22: Barrel Zone #2 Temp. (°F) | D22: - | E22: 610 | F22: -
B23: Barrel Zone #3 Temp. (°F) | D23: - | E23: 620 | F23: -
B24: Barrel Zone #4 Temp. (°F) | D24: - | E24: 650 | F24: -
B25: Barrel Zone #5 Temp. (°F) | D25: - | E25: 670 | F25: -
B26: Clamp Temp. (°F) | D26: - | E26: 690 | F26: -
B27: Neck/Flange (1D1) Temp. (°F) | D27: - | E27: 700 | F27: -
B28: Die Zone #1 (1D2) Temp. (°F) | D28: - | E28: 710 | F28: -
B29: Die Zone #2 (1D3) Temp. (°F) | D29: - | E29: 720 | F29: -
B30: Die Zone #3 (1D4) Temp. (°F) | D30: - | E30: - | F30: -
B31: Die Zone #4 (1D5) Temp. (°F) | D31: - | E31: - | F31: -
A32: Trough #1 Temp (°F) | D32: AIR
A33: Trough #2 Temp (°F) | D33: COLD WATER (60°F)
B34: Pay-Off Setting: grams psi | D34: - | E34: 25 | F34: -
B35: Tension Measured (grams) | D35: - | E35: - | F35: -
B36: Take-Up Tension (lbs) | D36: - | E36: 20 | F36: -
B37: Caterpuller (ft/min) | D37: - | E37: 39 | F37: -
B38: Spark Test (kV) | D38: 2
B39: Wall Thickness (in) | D39: - | E39: - | F39: -
B40: Final O.D. (in) | D40: 0.127 | E40: 0.131 | F40: 0.135
B41: Min. Concentricity (%) | D41: 0.85
B42: Max. Weight (lbs/1000ft) | D42: 20.7
...

Sheet SI Testing (Post-Jacket)
A1: Process Step | E1: Machine ID | I1: By | J1: Date
A2: SI Testing (Post-Jacket) | E2: VNA #1 | I2: ='Cover Sheet'!D2 -> CDC | J2: ='Cover Sheet'!E2 -> 46097 | K2: =#REF! -> #REF!
I4: REFERENCE AP96-048
B5: Electrical (Signal Integrity) Testing
B6: Operation # | C6: Description
B7: 1 | C7: Cut 25-foot section of cable, prep ends and terminate to test PCB.
B8: 2 | C8: Connect to Network Analyzer, enter job information and acquire data.
B9: 3 | C9: Print summary datasheet and include with job package.
B10: 4 | C10: Record "Pass/Fail" test result below.
H11: Actual | I11: Oper. | J11: Date
D12: Pass / Fail?
D13: Test Plot Attached?
B18: Notes:

Sheet Respooling-Marking RF
A1: Process Step | E1: Machine ID | J1: By | K1: Date
A2: Respooling/UV Laser Marking | E2: Respooler #1 | J2: ='Cover Sheet'!D2 -> CDC | K2: ='Cover Sheet'!E2 -> 46097 | L2: =#REF! -> #REF!
B4: REFERENCE AP96-054, AP96-058, AP96-059, AP96-060, AP96-061
B5: Materials
B6: Description | D6: Part Number | G6: Max Ft/Spool | J6: 1500
B7: Take-Up Spool | D7: AT12064 (11.75" X 7")
D9: Min. | E9: Nom. | F9: Max. | I9: Actual | J9: Oper. | K9: Date
B10: Line Speed (ft/min) | D10: - | E10: 100 | F10: -
B11: Spark Test (kV) | D11: 2
B13: UV Laser Marking
B14: Text Spacing (in) | C14: 12 MAX
B15: Print Legend | C15: GLENAIR BLUMARK 962-032-130 06324
B17: Samples for Test Lab | J17: Oper. | K17: Date
B18: Cut off 1 ft sample (qty:1). Package sample in bag. Label bag with part number and job number.
B20: Notes:
B21: NO SPLICES. SCRAP ALL LENGTHS LESS THAN 3 FT.

Sheet Packaging
A1: Process Step | E1: Machine ID | I1: By | J1: Date
A2: Packaging | E2: N/A | I2: ='Cover Sheet'!D2 -> CDC | J2: ='Cover Sheet'!E2 -> 46097 | K2: ='[2]Cover Sheet'!$F$2 -> SDB
H3: Reference SOP: AP96-067
B4: Create Tracer Ticket (PRDF 164A) with the following information: | G4: Total Footage:
B6: 1. Tracking # 2. Job # & Item # 3. Part Number 4. Qty 5. Date
H7: Oper. | I7: Date
B13: Per figure 1, seal both ends of the wire. Ends shall be sealed with shrink tubing or tape. Per figure 2, wrap spool/reel & tracer ticket with stretch wrap. | H13: Oper. | I13: Date
B30: Notes:
